<div>{{jsSidebar("Statements")}}</div>

<p>The <strong><code>try...catch</code> statement</strong> marks a block of statements to try, and specifies a response, should an exception be thrown.</p>

<h2 id="문법">문법</h2>

<pre class="syntaxbox">try {
   <em>try_statements</em>
}
[catch (<em>exception_var_1</em> if <em>condition_1</em>) { // 비표준
   <em>catch_statements_1</em>
}]
...
[catch (<em>exception_var_2</em>) {
   <em>catch_statements_2</em>
}]
[finally {
   <em>finally_statements</em>
}]
</pre>

<dl>
 <dt><code>try_statements</code></dt>
 <dd>실행될 선언들</dd>
</dl>

<dl>
 <dt><code>catch_statements_1</code>, <code>catch_statements_2</code></dt>
 <dd>try 블록에서 예외가 발생했을 때 실행될 선언들</dd>
</dl>

<dl>
 <dt><code>exception_var_1</code>, <code>exception_var_2</code></dt>
 <dd>catch 항목과 관련된 예외 객체를 담기 위한 식별자</dd>
</dl>

<dl>
 <dt><code>condition_1</code></dt>
 <dd>조건식</dd>
</dl>

<dl>
 <dt><code>finally_statements</code></dt>
 <dd>try 선언이 완료된 이후에 실행된 선언들. 이 선언들은 예외 발생 여부와 상관없이 실행된다.</dd>
</dl>

<h2 id="설명">설명</h2>

<p>try 선언의 구성은 하나 혹은 그 이상의 선언을 포함한 try 블록 및 catch 항목이나 finally 항목 중 최소한 하나 혹은 둘 다 포함하여 이루어진다. 즉, try 선언에는 세 가지 형식이 존재한다.</p>

<ol>
 <li><code>try...catch</code></li>
 <li><code>try...finally</code></li>
 <li><code>try...catch...finally</code></li>
</ol>

<p><code>catch</code>절은 <code>try</code> 블록 안에서 예외가 throw 되었을 때 무엇을 할지를 명시하는 기술(記述)을 포함합니다.  즉, 여러분은 <code>try</code> 블록이 성공하기를 원하고, 만약 성공하지 못했을 때 <code>catch</code>블록으로 제어를 넘기길 원할 것입니다. <code>try</code> 블록 (또는 <code>try</code> 블록 내에서 호출된 함수) 내의 명령문이 예외를 throw 하면 제어가 <code>catch</code> 절로 즉시 이동합니다. <code>try</code> 블록에 예외가 발생하지 않으면 <code>catch</code> 절을 건너뜁니다.</p>

<p><code>finally</code> 절은 <code>try</code> 블록과 <code>catch</code> 절 다음으로 실행됩니다. 예외사항의 throw 혹은 catch 여부에 관계없이 항상 실행됩니다.</p>

<p>하나 이상의 <code>try</code> 문을 중첩 할 수 있습니다. 내부의 <code>try</code> 문에 <code>catch</code> 문이 없으면, 둘러싼 <code>try</code> 문의 <code>catch</code> 절이 입력됩니다.</p>

<p>또한 <code>try</code> 문을 사용하여 예외처리를 합니다. 예외처리에 대해 더 알고 싶다면, <a href="/en-US/docs/Web/JavaScript/Guide" title="en/JavaScript/Guide">JavaScript Guide</a> 를 참고하세요.</p>

<h3 id="무조건적_catch_문">무조건적 <code>catch</code> 문</h3>

<p>무조건적 <code>catch</code> 문이 하나만 사용될경우, <code>catc</code>h 블럭은 예외사항이 throw 되었을때 항상 들어가집니다. 예를들어, 다음의 코드에 예외사항이 발생할때, 제어가 <code>catch</code> 문으로 이동하게 됩니다.</p>

<pre class="brush: js">try {
   throw "myException"; // generates an exception
}
catch (e) {
   // statements to handle any exceptions
   logMyErrors(e); // pass exception object to error handler
}
</pre>

<h3 id="조건적_catch_문">조건적 <code>catch</code> 문</h3>

<p>{{non-standard_header}}</p>

<p>또한 특정 예외사항에 대한 한개 또는 한개 이상의 조건적 <code>catch</code> 문을 사용할 수 있습니다. 이 경우에, 특정 예외사항에 따라 적절한 <code>catch</code> 문으로 이동하게 됩니다. 다음 예제에서, <code>try</code> 문 안의 코드는 세가지 예외사항: {{jsxref("TypeError")}}, {{jsxref("RangeError")}},{{jsxref("EvalError")}}을 throw 할 수 있습니다.. When an exception occurs, control transfers to the appropriate <code>catch</code> clause. If the exception is not one of the specified exceptions and an unconditional <code>catch</code> clause is found, control transfers to that <code>catch</code> clause.</p>

<p>If you use an unconditional <code>catch</code> clause with one or more conditional <code>catch</code> clauses, the unconditional <code>catch</code> clause must be specified last. Otherwise, the unconditional <code>catch</code> clause will intercept all types of exception before they can reach the conditional ones.</p>

<p>Reminder: this functionality is not part of the ECMAScript specification.</p>

<pre class="brush: js">try {
    myroutine(); // may throw three types of exceptions
} catch (e if e instanceof TypeError) {
    // statements to handle TypeError exceptions
} catch (e if e instanceof RangeError) {
    // statements to handle RangeError exceptions
} catch (e if e instanceof EvalError) {
    // statements to handle EvalError exceptions
} catch (e) {
    // statements to handle any unspecified exceptions
    logMyErrors(e); // pass exception object to error handler
}
</pre>

<p>And here is how to do implement the same "Conditional catch clauses" using only simple JavaScript conforming to the ECMAScript specification (obviously it's more verbose, but works everywhere):</p>

<pre class="brush: js">try {
    myroutine(); // may throw three types of exceptions
} catch (e) {
    if (e instanceof TypeError) {
        // statements to handle TypeError exceptions
    } else if (e instanceof RangeError) {
        // statements to handle RangeError exceptions
    } else if (e instanceof EvalError) {
        // statements to handle EvalError exceptions
    } else {
       // statements to handle any unspecified exceptions
       logMyErrors(e); // pass exception object to error handler
    }
}
</pre>

<h3 id="The_exception_identifier">The exception identifier</h3>

<p>When an exception is thrown in the <code>try</code> block, <em><code>exception_var</code></em> (e.g. the <code>e</code> in <code>catch (e)</code>) holds the value specified by the <code>throw</code> statement. You can use this identifier to get information about the exception that was thrown.</p>

<p>This identifier is local to the <code>catch</code> clause. That is, it is created when the <code>catch</code> clause is entered, and after the <code>catch</code> clause finishes executing, the identifier is no longer available.</p>

<h3 id="The_finally_clause">The <code>finally</code> clause</h3>

<p>The <code>finally</code> clause contains statements to execute after the <code>try</code> block and <code>catch</code> clause(s) execute, but before the statements following the <code>try</code> statement. The <code>finally</code> clause executes regardless of whether or not an exception is thrown. If an exception is thrown, the statements in the <code>finally</code> clause execute even if no <code>catch</code> clause handles the exception.</p>

<p>You can use the <code>finally</code> clause to make your script fail gracefully when an exception occurs; for example, you may need to release a resource that your script has tied up. The following example opens a file and then executes statements that use the file (server-side JavaScript allows you to access files). If an exception is thrown while the file is open, the <code>finally</code> clause closes the file before the script fails. The code in <code>finally</code> also executes upon explicitly returning from <code>try</code> or <code>catch</code> block.</p>

<pre class="brush: js">openMyFile()
try {
   // tie up a resource
   writeMyFile(theData);
}
finally {
   closeMyFile(); // always close the resource
}
</pre>

<h2 id="Examples">Examples</h2>

<h3 id="Nested_try-blocks">Nested try-blocks</h3>

<p>First let's see what happens with this:</p>

<pre class="brush: js">try {
  try {
    throw new Error("oops");
  }
  finally {
    console.log("finally");
  }
}
catch (ex) {
  console.error("outer", ex.message);
}

// Output:
// "finally"
// "outer" "oops"
</pre>

<p>Now, if we already caught the exception in the inner try-block by adding a catch block</p>

<pre class="brush: js">try {
  try {
    throw new Error("oops");
  }
  catch (ex) {
    console.error("inner", ex.message);
  }
  finally {
    console.log("finally");
  }
}
catch (ex) {
  console.error("outer", ex.message);
}

// Output:
// "inner" "oops"
// "finally"
</pre>

<p>And now, lets re-throw the error.</p>

<pre class="brush: js">try {
  try {
    throw new Error("oops");
  }
  catch (ex) {
    console.error("inner", ex.message);
    throw ex;
  }
  finally {
    console.log("finally");
  }
}
catch (ex) {
  console.error("outer", ex.message);
}

// Output:
// "inner" "oops"
// "finally"
// "outer" "oops"
</pre>

<p>Any given exception will be caught only once by the nearest enclosing catch-block, unless it is re-thrown. Of course, any new exceptions raised in the "inner" block (because code in catch-block may do something that throws), will be caught by the "outer" block.</p>

<h3 id="Returning_from_a_finally_block">Returning from a finally block</h3>

<p>If the <code>finally</code> block returns a value, this value becomes the return value of the entire <code>try-catch-finally</code> production, regardless of any <code>return</code> statements in the <code>try</code> and <code>catch</code> blocks. This includes exceptions thrown inside of the catch block:</p>

<pre class="brush: js">try {
  try {
    throw new Error("oops");
  }
  catch (ex) {
    console.error("inner", ex.message);
    throw ex;
  }
  finally {
    console.log("finally");
    return;
  }
}
catch (ex) {
  console.error("outer", ex.message);
}

// Output:
// "inner" "oops"
// "finally"
</pre>

<p>The outer "oops" is not thrown because of the return in the finally block. The same would apply to any value returned from the catch block.</p>

<h2 id="Specifications">Specifications</h2>

<table class="standard-table">
 <tbody>
  <tr>
   <th scope="col">Specification</th>
   <th scope="col">Status</th>
   <th scope="col">Comment</th>
  </tr>
  <tr>
   <td>{{SpecName('ES3')}}</td>
   <td>{{Spec2('ES3')}}</td>
   <td>Initial definition. Implemented in JavaScript 1.4</td>
  </tr>
  <tr>
   <td>{{SpecName('ES5.1', '#sec-12.14', 'try statement')}}</td>
   <td>{{Spec2('ES5.1')}}</td>
   <td></td>
  </tr>
  <tr>
   <td>{{SpecName('ES6', '#sec-try-statement', 'try statement')}}</td>
   <td>{{Spec2('ES6')}}</td>
   <td></td>
  </tr>
  <tr>
   <td>{{SpecName('ESDraft', '#sec-try-statement', 'try statement')}}</td>
   <td>{{Spec2('ESDraft')}}</td>
   <td>Not part of the current ECMA-262 standard: Multiple catch clauses and conditional clauses (SpiderMonkey extension, JavaScript 1.5).</td>
  </tr>
 </tbody>
</table>

<h2 id="Browser_compatibility">Browser compatibility</h2>

<p>{{CompatibilityTable}}</p>

<div id="compat-desktop">
<table class="compat-table">
 <tbody>
  <tr>
   <th>Feature</th>
   <th>Chrome</th>
   <th>Firefox (Gecko)</th>
   <th>Internet Explorer</th>
   <th>Opera</th>
   <th>Safari</th>
  </tr>
  <tr>
   <td>Basic support</td>
   <td>{{CompatVersionUnknown}}</td>
   <td>{{CompatVersionUnknown}}</td>
   <td>{{CompatVersionUnknown}}</td>
   <td>{{CompatVersionUnknown}}</td>
   <td>{{CompatVersionUnknown}}</td>
  </tr>
  <tr>
   <td>Conditional clauses<br>
    (non-standard)</td>
   <td>{{CompatNo}}</td>
   <td>{{CompatVersionUnknown}}</td>
   <td>{{CompatNo}}</td>
   <td>{{CompatNo}}</td>
   <td>{{CompatNo}}</td>
  </tr>
 </tbody>
</table>
</div>

<div id="compat-mobile">
<table class="compat-table">
 <tbody>
  <tr>
   <th>Feature</th>
   <th>Android</th>
   <th>Chrome for Android</th>
   <th>Firefox Mobile (Gecko)</th>
   <th>IE Mobile</th>
   <th>Opera Mobile</th>
   <th>Safari Mobile</th>
  </tr>
  <tr>
   <td>Basic support</td>
   <td>{{CompatVersionUnknown}}</td>
   <td>{{CompatVersionUnknown}}</td>
   <td>{{CompatVersionUnknown}}</td>
   <td>{{CompatVersionUnknown}}</td>
   <td>{{CompatVersionUnknown}}</td>
   <td>{{CompatVersionUnknown}}</td>
  </tr>
  <tr>
   <td>Conditional clauses<br>
    (non-standard)</td>
   <td>{{CompatNo}}</td>
   <td>{{CompatNo}}</td>
   <td>{{CompatVersionUnknown}}</td>
   <td>{{CompatNo}}</td>
   <td>{{CompatNo}}</td>
   <td>{{CompatNo}}</td>
  </tr>
 </tbody>
</table>
</div>

<h2 id="See_also">See also</h2>

<ul>
 <li>{{jsxref("Error")}}</li>
 <li>{{jsxref("Statements/throw", "throw")}}</li>
</ul>