<div>{{jsSidebar("Statements")}}</div>

<p>The <strong><code>try...catch</code></strong> statement marks a block of statements to try, and specifies a response, should an exception be thrown.</p>

<div>{{EmbedInteractiveExample("pages/js/statement-trycatch.html")}}</div>

<p class="hidden">The source for this interactive example is stored in a GitHub repository. If you'd like to contribute to the interactive examples project, please clone <a href="https://github.com/mdn/interactive-examples">https://github.com/mdn/interactive-examples</a> and send us a pull request.</p>

<h2 id="Syntax">Syntax</h2>

<pre class="syntaxbox">try {
  <em>try_statements</em>
}
[catch (<em>exception_var_1</em> if <em>condition_1</em>) { // non-standard
  <em>catch_statements_1</em>
}]
...
[catch (<em>exception_var_2</em>) {
  <em>catch_statements_2</em>
}]
[finally {
  <em>finally_statements</em>
}]
</pre>

<dl>
 <dt><code>try_statements</code></dt>
 <dd>The statements to be executed.</dd>
</dl>

<dl>
 <dt><code>catch_statements_1</code>, <code>catch_statements_2</code></dt>
 <dd>Statements that are executed if an exception is thrown in the <code>try</code>-block.</dd>
</dl>

<dl>
 <dt><code>exception_var_1</code>, <code>exception_var_2</code></dt>
 <dd>An identifier to hold an exception object for the associated <code>catch</code>-block.</dd>
</dl>

<dl>
 <dt><code>condition_1</code></dt>
 <dd>A conditional expression.</dd>
</dl>

<dl>
 <dt><code>finally_statements</code></dt>
 <dd>Statements that are executed after the <code>try</code> statement completes. These statements execute regardless of whether an exception was thrown or caught.</dd>
</dl>

<h2 id="Description">Description</h2>

<p>The <code>try</code> statement consists of a <code>try</code>-block, which contains one or more statements. <code>{}</code> must always be used, even for single statements. At least one <code>catch</code>-block, or a <code>finally</code>-block, must be present. This gives us three forms for the <code>try</code> statement:</p>

<ul>
 <li><code>try...catch</code></li>
 <li><code>try...finally</code></li>
 <li><code>try...catch...finally</code></li>
</ul>

<p>A <code>catch</code>-block contains statements that specify what to do if an exception is thrown in the <code>try</code>-block. If any statement within the <code>try</code>-block (or in a function called from within the <code>try</code>-block) throws an exception, control is immediately shifted to the <code>catch</code>-block. If no exception is thrown in the <code>try</code>-block, the <code>catch</code>-block is skipped.</p>

<p>The <code>finally</code>-block will always execute after the <code>try</code>-block and <code>catch</code>-block(s) have finished executing. It always executes, regardless of whether an exception was thrown or caught.</p>

<p>You can nest one or more <code>try</code> statements. If an inner <code>try</code> statement does not have a <code>catch</code>-block, the enclosing <code>try</code> statement's <code>catch</code>-block is used instead.</p>

<p>You can also use the <code>try</code> statement to handle JavaScript exceptions. See the <a href="/en-US/docs/Web/JavaScript/Guide" title="en/JavaScript/Guide">JavaScript Guide</a> for more information on JavaScript exceptions.</p>

<h3 id="Unconditional_catch-block">Unconditional catch-block</h3>

<p>When a  <code>catch</code>-block is used, the <code>catch</code>-block is executed when any exception is thrown from within the <code>try</code>-block. For example, when the exception occurs in the following code, control transfers to the <code>catch</code>-block.</p>

<pre class="brush: js">try {
  throw 'myException'; // generates an exception
}
catch (e) {
  // statements to handle any exceptions
  logMyErrors(e); // pass exception object to error handler
}
</pre>

<p>The <code>catch</code>-block specifies an identifier (<code>e</code> in the example above) that holds the value of the exception; this value is only available in the <a href="/en-US/docs/Glossary/Scope">scope</a> of the <code>catch</code>-block.</p>

<h3 id="Conditional_catch-blocks">Conditional catch-blocks</h3>

<p>{{non-standard_header}}</p>

<p>You can also use one or more conditional <code>catch</code>-blocks to handle specific exceptions. In this case, the appropriate <code>catch</code>-block is entered when the specified exception is thrown. In the following example, code in the <code>try</code>-block can potentially throw three exceptions: {{jsxref("TypeError")}}, {{jsxref("RangeError")}}, and {{jsxref("EvalError")}}. When an exception occurs, control transfers to the appropriate <code>catch</code>-block. If the exception is not one of the specified exceptions and an unconditional <code>catch</code>-block is found, control transfers to that <code>catch</code>-block.</p>

<p>If you use an unconditional <code>catch</code>-block with one or more conditional <code>catch</code>-blocks, the unconditional <code>catch</code>-block must be specified last. Otherwise, the unconditional <code>catch</code>-block will intercept all types of exception before they can reach the conditional ones.</p>

<p>Reminder: this functionality is not part of the ECMAScript specification and has been removed in Firefox 59. It's not supported in any current browser anymore.</p>

<pre class="brush: js">try {
  myroutine(); // may throw three types of exceptions
} catch (e if e instanceof TypeError) {
  // statements to handle TypeError exceptions
} catch (e if e instanceof RangeError) {
  // statements to handle RangeError exceptions
} catch (e if e instanceof EvalError) {
  // statements to handle EvalError exceptions
} catch (e) {
  // statements to handle any unspecified exceptions
  logMyErrors(e); // pass exception object to error handler
}
</pre>

<p>Here is the same "Conditional <code>catch</code>-blocks" using code that conforms to ECMAScript specification (obviously it's verbose, but works everywhere):</p>

<pre class="brush: js">try {
  myroutine(); // may throw three types of exceptions
} catch (e) {
  if (e instanceof TypeError) {
    // statements to handle TypeError exceptions
  } else if (e instanceof RangeError) {
    // statements to handle RangeError exceptions
  } else if (e instanceof EvalError) {
    // statements to handle EvalError exceptions
  } else {
    // statements to handle any unspecified exceptions
    logMyErrors(e); // pass exception object to error handler
  }
}
</pre>

<p>One reason for using the old conditional try-block is for only catching (and silencing) a small subset of expected errors. You can instead re-throw the error if you want this behavior:</p>

<pre class="brush: js">try {
  myRoutine();
} catch (e) {
  if (e instanceof RangeError) {
    // statements to handle this very common expected error
  } else {
    throw e;  // re-throw the error unchanged
  }
}
</pre>

<h3 id="The_exception_identifier">The exception identifier</h3>

<p>When an exception is thrown in the <code>try</code>-block, <em><code>exception_var</code></em> (i.e., the <code>e</code> in <code>catch (e)</code>) holds the exception value. You can use this identifier to get information about the exception that was thrown. This identifier is only available in the <code>catch</code>-block's <a href="/en-US/docs/Glossary/Scope">scope</a>.</p>

<pre class="brush: js">function isValidJSON(text) {
  try {
    JSON.parse(text);
    return true;
  } catch {
    return false;
  }
}
</pre>

<h3 id="The_finally-block">The finally-block</h3>

<p>The <code>finally</code>-block contains statements to execute after the <code>try</code>-block and <code>catch</code>-block(s) execute, but before the statements following the <code>try...catch...finally</code>-block. Note that the <code>finally</code>-block executes regardless of whether an exception is thrown. Also, if an exception is thrown, the statements in the <code>finally</code>-block execute even if no <code>catch</code>-block handles the exception.</p>

<p>The following example shows one use case for the <code>finally</code>-block. The code opens a file and then executes statements that use the file; the <code>finally</code>-block makes sure the file always closes after it is used even if an exception was thrown.</p>

<pre class="brush: js">openMyFile();
try {
  // tie up a resource
  writeMyFile(theData);
}
finally {
  closeMyFile(); // always close the resource
}
</pre>

<h2 id="Examples">Examples</h2>

<h3 id="Nested_try-blocks">Nested try-blocks</h3>

<p>First, let's see what happens with this:</p>

<pre class="brush: js">try {
  try {
    throw new Error('oops');
  }
  finally {
    console.log('finally');
  }
}
catch (ex) {
  console.error('outer', ex.message);
}

// Output:
// "finally"
// "outer" "oops"
</pre>

<p>Now, if we already caught the exception in the inner <code>try</code>-block by adding a <code>catch</code>-block</p>

<pre class="brush: js">try {
  try {
    throw new Error('oops');
  }
  catch (ex) {
    console.error('inner', ex.message);
  }
  finally {
    console.log('finally');
  }
}
catch (ex) {
  console.error('outer', ex.message);
}

// Output:
// "inner" "oops"
// "finally"
</pre>

<p>And now, let's rethrow the error.</p>

<pre class="brush: js">try {
  try {
    throw new Error('oops');
  }
  catch (ex) {
    console.error('inner', ex.message);
    throw ex;
  }
  finally {
    console.log('finally');
  }
}
catch (ex) {
  console.error('outer', ex.message);
}

// Output:
// "inner" "oops"
// "finally"
// "outer" "oops"
</pre>

<p>Any given exception will be caught only once by the nearest enclosing <code>catch</code>-block unless it is rethrown. Of course, any new exceptions raised in the "inner" block (because the code in <code>catch</code>-block may do something that throws), will be caught by the "outer" block.</p>

<h3 id="Returning_from_a_finally-block">Returning from a finally-block</h3>

<p>If the <code>finally</code>-block returns a value, this value becomes the return value of the entire <code>try-catch-finally</code> statement, regardless of any <code>return</code> statements in the <code>try</code> and <code>catch</code>-blocks. This includes exceptions thrown inside of the <code>catch</code>-block:</p>

<pre class="brush: js">(function() {
  try {
    try {
      throw new Error('oops');
    }
    catch (ex) {
      console.error('inner', ex.message);
      throw ex;
    }
    finally {
      console.log('finally');
      return;
    }
  }
  catch (ex) {
    console.error('outer', ex.message);
  }
})();

// Output:
// "inner" "oops"
// "finally"</pre>

<p>The outer "oops" is not thrown because of the return in the <code>finally</code>-block. The same would apply to any value returned from the <code>catch</code>-block.</p>

<h2 id="Specifications">Specifications</h2>

<table class="standard-table">
 <tbody>
  <tr>
   <th scope="col">Specification</th>
   <th scope="col">Status</th>
   <th scope="col">Comment</th>
  </tr>
  <tr>
   <td>{{SpecName('ES3')}}</td>
   <td>{{Spec2('ES3')}}</td>
   <td>Initial definition. Implemented in JavaScript 1.4</td>
  </tr>
  <tr>
   <td>{{SpecName('ES5.1', '#sec-12.14', 'try statement')}}</td>
   <td>{{Spec2('ES5.1')}}</td>
   <td></td>
  </tr>
  <tr>
   <td>{{SpecName('ES6', '#sec-try-statement', 'try statement')}}</td>
   <td>{{Spec2('ES6')}}</td>
   <td></td>
  </tr>
  <tr>
   <td>{{SpecName('ESDraft', '#sec-try-statement', 'try statement')}}</td>
   <td>{{Spec2('ESDraft')}}</td>
   <td>Not part of the current ECMA-262 standard: Multiple catch-blocks and conditional-blocks (SpiderMonkey extension, JavaScript 1.5).</td>
  </tr>
 </tbody>
</table>

<h2 id="Browser_compatibility">Browser compatibility</h2>

<div class="hidden">The compatibility table on this page is generated from structured data. If you'd like to contribute to the data, please check out <a href="https://github.com/mdn/browser-compat-data">https://github.com/mdn/browser-compat-data</a> and send us a pull request.</div>

<p>{{Compat("javascript.statements.try_catch")}}</p>

<h2 id="See_also">See also</h2>

<ul>
 <li>{{jsxref("Error")}}</li>
 <li>{{jsxref("Statements/throw", "throw")}}</li>
</ul>